Workbook
Name AMENAZARAS: [1]CÁLCULOS!$B$29:$B$30
Name arriba3d: #REF!
Name ARRIBA4A: #REF!
Name ARRIBADOSA: #REF!
Name ARRIBADOSABE: #REF!
Name ARRIBADUOSAAA: '[2]1a. Misión, Visión'!#REF!
Name ARRIBAFACTCLAU: #REF!
Name ARRIBAIMPRIMIR: #REF!
Name BUSCARMES: #REF!
Name DEBILIDAD: #REF!
Name ESTRATEGIA: #REF!
Name EXTERNAS: #REF!
Name FLUJODECAJA: #REF!
Name FORTALEZAS: #REF!
Name GRAFIK2a6: #REF!
Name INDICE: [2]INDICE!#REF!
Name INFO2a6: #REF!
Name INFO2E: #REF!
Name INFO2F: #REF!
Name INFO2G: #REF!
Name INFO3A: #REF!
Name INFO3B: #REF!
Name info3ce: #REF!
Name INFO4A: #REF!
Name INFOADL: #REF!
Name infoBCG: #REF!
Name INFODOSA: #REF!
Name INFODOSABE: #REF!
Name INFODOSBE: #REF!
Name INFODUOSAAA: '[2]1a. Misión, Visión'!#REF!
Name INFOINDICE: [2]INDICE!#REF!
Name INFOPLAN: [2]INDICE!#REF!
Name INFOSTRATEGICPLAN: [2]INDICE!#REF!
Name INFOUNOBE: #REF!
Name INFOUNOCE: #REF!
Name INTENSIDAD: [1]CÁLCULOS!$B$22:$B$26
Name INVERSION: #REF!
Name Menor: "Severidad"
Name Naturaleza: [3]Ponderación!$A$2:$B$8
Name Naturaleza: Ponderación!$A$2:$B$11
Name nomeses: #REF!
Name NUMES: #REF!
Name PESTPEST: '[1]3a'!#REF!
Name PLANNINGSALES: [2]INDICE!#REF!
Name PONERDATOS: #REF!
Name Probabilidad: [3]Ponderación!$D$2:$E$4
Name Probabilidad: Ponderación!$D$2:$E$4
Name PUBLICIDAD: [2]INDICE!#REF!
Name Severidad: [3]Ponderación!$G$2:$H$4
Name Severidad: Ponderación!$G$2:$H$5
Name trescece: #REF!

Sheet INDICE
C2: INSTITUTO NACIONAL ELECTORAL JLE NAYARIT | K2: Versión: 0
C3: SISTEMA DE GESTIÓN DE LA CALIDAD | K3: Fecha de emisión:
C4: PLAN ESTRATÉGICO | K4: 43854
A8: 1a. Misión, Visión y Valores | D8: 2a. Análisis FODA | G8: 3a. Matriz Partes Interesadas | J8: 4a. Parámetros de riesgo
A9: 1b. Política de Calidad y Objetivos de Calidad | D9: 2b. Matriz Posicionamiento Estratégico | J9: 4b. Matriz - Contexto
A12: Denominación (abreviada): | D12: JLE NAYARIT | G12: ◄ Indica aquí el nombre de la Junta Local Ejecutiva
A14: Período de vigencia del plan: | D14: 2020-2021 | G14: ◄ Indica aquí el período del plan.
A16: Primer ejercicio: | D16: 43854 | G16: ◄ Primer ejercicio (año) del plan.
A18: RESPONSABLE | C18: ROL | F18: NOMBRE | I18: FIRMA
A19: Elaboración: | C19: Coordinadores de la Calidad | F19: Lic. María Concepción Maldonado Soto Mtra. Luz Elena Rodríguez López C. Raúl Carrillo Manríquez
A20: Revisión: | C20: Alta Dirección | F20: Mtro. Ignacio Rodríguez Villaseñor
A21: Aprobación: | C21: Alta Dirección | F21: Mtro. Eduardo Manuel Trujillo Trujillo Mtra. Verónica Sandoval Castañeda Lic. Pablo García Martínez

Sheet INTRO
D1: INSTITUTO NACIONAL ELECTORAL JLE NAYARIT | L1: Versión: 0
D2: SISTEMA DE GESTIÓN DE LA CALIDAD | L2: Fecha de emisión:
D3: PLAN ESTRATÉGICO | L3: 43854
B5: ¿QUÉ ENTENDEMOS COMO PLAN ESTRATÉGICO?
B6: Entendemos por "Plan Estratégico" aquel que, partiendo de lo que la Institución es hoy o de lo que se quiere ser (si aún no existe), analiza la situación dónde nos encontramos y define dónde, cómo y cuándo llegaremos. Por tanto, siempre es un plan a medio/largo plazo que contiene elementos "filosóficos”, elementos analíticos y elementos operativos sostenidos y confirmados por las consiguientes previsiones económico - financieras.
B10: ESTRUCTURA DE UN "PLAN ESTRATÉGICO"
C12: CONCEPTOS - FILOSOFÍA ← | H12: Misión, Visión, Valores
C13: Elementos conceptuales: Quiénes somos, donde queremos llegar.
C15: ANÁLISIS ESTRATÉGICO ← | H15: Entorno y coyuntura
C16: Análisis: Dónde estamos y cual es el entorno. Situación y factores internos y externos. Posición competitiva Qué opciones estratégicas tenemos. | H16: Situación interna y externa
H17: Posición competitiva
H18: Modelo de negocio
C19: CONCLUSIONES, OBJETIVOS Y ESTRATEGIA ← | H19: Conclusiones y objetivos
C20: Definición: Qué objetivos, cómo y cuando los alcanzaremos. Que estrategias aplicaremos. | H20: Objetivos, metas y estrategias

Sheet 1a. Misión, Visión
B1: INSTITUTO NACIONAL ELECTORAL JLE NAYARIT | J1: Versión: 0
B2: SISTEMA DE GESTIÓN DE LA CALIDAD | J2: Fecha de emisión:
B3: PLAN ESTRATÉGICO | J3: 43854
B6: =INDICE!D12 -> JLE NAYARIT | D6: MISIÓN | H6: =INDICE!D14 -> 2020-2021
K7: |
B8: Organizar procesos electorales libres equitativos y confiables, para garantizar el ejercicio de los derechos políticos-electorales de la ciudadanía y contribuir al desarrollo de la vida democrática de México.
B11: =INDICE!D12 -> JLE NAYARIT | D11: VISIÓN | H11: =INDICE!D14 -> 2020-2021
B13: Ser el organismo electoral nacional autónomo que contribuya a la consolidación de la cultura y convivencia democrática en México, distinguiéndose por ser una institución, moderna, trasparente y eficiente en la que la sociedad confíe plenamente para la organización de lecciones equitativas e imparciales.
B16: =INDICE!D12 -> JLE NAYARIT | D16: VALORES ORGANIZACIONALES | H16: =INDICE!D14 -> 2020-2021
B18: Confianza, Tolerancia, Compromiso, Trasparencia y Rendición de Cuentas.
B19: =INDICE!D12 -> JLE NAYARIT | D19: PRINCIPIOS RECTORES | H19: =INDICE!D14 -> 2020-2021
B21: Certeza, Legalidad, Independencia, Imparcialidad, Objetividad y Máxima Publicidad.

Sheet 1b. Política y Objetivos
C1: INSTITUTO NACIONAL ELECTORAL JLE NAYARIT | N1: Versión: 0
C2: SISTEMA DE GESTIÓN DE LA CALIDAD | N2: Fecha de emisión:
C4: PLAN ESTRATÉGICO | N4: 43854
B6: POLÍTICA DE CALIDAD
B7: En el Instituto Nacional Electoral INE, estamos comprometidos en proporcionar a la ciudadanía un servicio eficiente y de calidad en el trámite de expedición de su credencial para votar, desde la entrevista hasta la entrega de la credencial para votar, para contribuir al derecho a la identidad ciudadana, con base en el marco normativo, reglamentario y en un entorno de mejora continua con apego a los requisitos de la norma ISO 9001:2015.
B10: OBJETIVOS DE LA CALIDAD
B11: 1. Actualizar el Padrón Electoral en la entidad mediante la captación de solicitudes de credencial requeridas por la ciudadanía en los Módulos de Atención Ciudadana Instalados. 2. Elevar el porcentaje de utilización de la capacidad en los Módulos de Atención Ciudadana de la Entidad. 3. Brindar el servicio en todos los Módulos de Atención Ciudadana autorizados en el estado, conforme al calendario de operación de Módulos de Atención Ciudadana de la campaña de actualización en turno. 4. Promover la inscripción de jóvenes al Padrón Electoral. 5. Mantener el servicio de atención a domicilio, acorde a lo que establece el artículo 141 de la Ley General de Instituciones y Procedimientos Electorales (LGIPE). 6. Conocer la opinión ciudadana sobre el servicio de los Módulos de Atención Ciudadana.

Sheet 2a. Análisis Foda
C1: INSTITUTO NACIONAL ELECTORAL | R1: Versión: 0
C3: JUNTA LOCAL EJECUTIVA DE NAYARIT | R3: Fecha de emisión:
C5: FODA | R5: 43854
B8: FORTALEZAS (F) | F8: DESACUERDO | G8: NI DE ACUERDO NI EN DESACUERDO | H8: DE ACUERDO | I8: VALOR | L8: DEBILIDADES (D) | P8: DESACUERDO | Q8: NI DE ACUERDO NI EN DESACUERDO | R8: DE ACUERDO | S8: VALOR
F9: 1 | G9: 2 | H9: 3 | P9: 1 | Q9: 2 | R9: 3
B10: Se tiene una planeación de Directorio de Módulos. | H10: X | I10: =SUMIF(F10:H10, "X",$F$9:$H$9) -> 3 | L10: Metodología deficiente para la capacitación. | R10: X | S10: =SUMIF(P10:R10,"X",P$9:R$9) -> 3
B11: Atención a Ciudadanos con problemas de movilización. | H11: X | I11: =SUMIF(F11:H11, "X",$F$9:$H$9) -> 3 | L11: Falta de oportunidad en la disposición de recursos. | R11: X | S11: =SUMIF(P11:R11,"X",P$9:R$9) -> 3
B12: Compromiso institucional de la Alta Dirección del Instituto. | H12: X | I12: =SUMIF(F12:H12, "X",$F$9:$H$9) -> 3 | L12: Esquema contractual del personal de Módulos de Atención Ciudadana. | R12: X | S12: =SUMIF(P12:R12,"X",P$9:R$9) -> 3
B13: Personal experimentado en Módulos de Atención Ciudadana. | H13: X | I13: =SUMIF(F13:H13, "X",$F$9:$H$9) -> 3 | L13: Falta de competencias del personal de Módulos de Atención Ciudadana para la atención de situaciones complejas y no comunes. | R13: X | S13: =SUMIF(P13:R13,"X",P$9:R$9) -> 3
B14: Procedimientos estandarizados en manuales y lineamientos. | H14: X | I14: =SUMIF(F14:H14, "X",$F$9:$H$9) -> 3 | L14: Falta de conocimiento del personal de las funciones de otras áreas de la Institución | R14: X | S14: =SUMIF(P14:R14,"X",P$9:R$9) -> 3
B15: Conocimiento de la normatividad por parte del personal. | G15: X | I15: =SUMIF(F15:H15, "X",$F$9:$H$9) -> 2 | L15: Incumplimiento de tiempos en la entrega de la Credencia para Votar. | R15: X | S15: =SUMIF(P15:R15,"X",P$9:R$9) -> 3
B16: Fideicomiso para la infraestructura de Módulos de Atención Ciudadana. | H16: X | I16: =SUMIF(F16:H16, "X",$F$9:$H$9) -> 3 | L16: Falta de actualizaciones eficientes en el SIIRFE-MAC. | P16: X | S16: =SUMIF(P16:R16,"X",P$9:R$9) -> 1
B17: Profesionalización de los MSPEN . | H17: X | I17: =SUMIF(F17:H17, "X",$F$9:$H$9) -> 3 | L17: Infraestructura insuficiente para la operación de los Módulos de Atención Ciudadana AC (humanos, materiales y financieros). | R17: X | S17: =SUMIF(P17:R17,"X",P$9:R$9) -> 3
B18: Actualización constante de equipo tecnológico y sistemas informáticos. | H18: X | I18: =SUMIF(F18:H18, "X",$F$9:$H$9) -> 3 | L18: Falta de compatibilidad de normas administrativas con operativas. | R18: X | S18: =SUMIF(P18:R18,"X",P$9:R$9) -> 3
B19: Actualización cartográfica permanente. | H19: X | I19: =SUMIF(F19:H19, "X",$F$9:$H$9) -> 3 | L19: Desconocimiento de la misión, visión y objetivos Institucionales por parte del personal. | R19: X | S19: =SUMIF(P19:R19,"X",P$9:R$9) -> 3
B20: Las medidas de seguridad en el control de los registros y datos personales. | H20: X | I20: =SUMIF(F20:H20, "X",$F$9:$H$9) -> 3
B21: Gratuidad de la Credencial para Votar. | H21: X | I21: =SUMIF(F21:H21, "X",$F$9:$H$9) -> 3
B24: TOTAL | I24: =SUM(I10:I23) -> 35 | J24: =I24 -> 35 | L24: TOTAL | S24: =SUM(S10:S23)*-1 -> -28 | T24: =S24*-1 -> 28 | U24: =(S24*$K$53)/$M$53 -> -5.0909091 | W24: =(I24*$K$54)/$M$54 -> 12
B27: Parámetros de análisis situacional de la Organización: | L27: COORDENADAS (EJES)
B28: 1. Fortalezas y Debilidades: | D28: 2. Amenazas y Oportunidades | L28: X | M28: Valor proporcional D + O | N28: =O28 -> 0
B29: a) Dar 1 punto por cada X en desacuerdo | D29: a) Dar 1 punto por cada X bajo No | L29: Y | M29: Valor proporcional F + A | N29: =O29 -> 0
B30: b) Dar 2 puntos por cada X bajo ni acuerdo o en desacuerdo | D30: b) Dar 2 puntos por cada X bajo puede ser | K30: 6 | L30: X | M30: =MAX(#REF!) -> #REF!
B31: c) Dar 3 puntos por cada X bajo acuerdo | D31: c) Dar 3 puntos por cada X bajo Sí | K31: 12 | L31: Y | M31: =MAX(#REF!) -> #REF!
B34: AMENAZAS (A) | F34: NO | G34: PUEDE SER | H34: SI | I34: VALOR | L34: OPORTUNIDADES (O) | P34: NO | Q34: PUEDE SER | R34: SI | S34: VALOR
B35: Los recortes presupuestales afectan la operación de los proyectos del Registro Federal de Electores. | H35: X | I35: =SUMIF(F35:H35, "X",$F$9:$H$9) -> 3 | L35: Fortalecer el uso de los medios de comunicación para informar a la ciudadanía sobre los requisitos para el trámite de la Credencia para Votar. | R35: X | S35: =SUMIF(P35:R35,"X",$P$9:$R$9) -> 3
B36: Falta de medidas de control de las Dependencias que emiten documentos de identidad que provocan registros irregulares y/o duplicados. | H36: X | I36: =SUMIF(F36:H36, "X",$F$9:$H$9) -> 3 | L36: Dotación de recursos para la operación del Módulo de Atención Ciudadana encargado de dar cumplimiento a solicitudes de incorporación al padrón por artículo 141. | P36: X | S36: =SUMIF(P36:R36,"X",$P$9:$R$9) -> 1
B37: Condiciones de inseguridad en zonas identificadas de alto riesgo para la operación de los Módulos de Atención Ciudadana. | H37: X | I37: =SUMIF(F37:H37, "X",$F$9:$H$9) -> 3 | L37: Aprovechar el reconocimiento de la credencial para votar como medio de identificación confiable, para formalizar alianzas con otras Instituciones. | R37: X | S37: =SUMIF(P37:R37,"X",$P$9:$R$9) -> 3
B38: Pérdida de interés de la credencial para votar como documento de identidad ante la potencial existencia de la cédula de identidad. | H38: X | I38: =SUMIF(F38:H38, "X",$F$9:$H$9) -> 3 | L38: Reducir el tiempo de entrega de la Credencial para Votar a la Ciudadanía para satisfacer su necesidad de realizar algún trámite. | R38: X | S38: =SUMIF(P38:R38,"X",$P$9:$R$9) -> 3
B39: La confianza institucional disminuye por declaraciones negativas de actores políticos. | H39: X | I39: =SUMIF(F39:H39, "X",$F$9:$H$9) -> 3 | L39: Gestionar con Instituciones que realicen detección de necesidades y evaluación de clima laboral. | Q39: X | S39: =SUMIF(P39:R39,"X",$P$9:$R$9) -> 2
B40: El uso de las redes sociales para campañas negativas hacia el Instituto por medio de: fake news, boots y trolls, influye de manera negativa en la percepción Ciudadana sobre el desempeño Institucional. | H40: X | I40: =SUMIF(F40:H40, "X",$F$9:$H$9) -> 3 | L40: La colaboración de las autoridades municipales para otorgar el uso de espacios que sirvan para operar Módulos de Atención Ciudadana itinerantes. | R40: X | S40: =SUMIF(P40:R40,"X",$P$9:$R$9) -> 3
B41: Falta de servicios públicos y vías de comunicación en zonas de difícil acceso que repercuten en la adecuada atención a la ciudadanía. | H41: X | I41: =SUMIF(F41:H41, "X",$F$9:$H$9) -> 3 | L41: Fortalecer los vínculos con Instituciones de educación para aumentar las competencias del personal. | R41: X | S41: =SUMIF(P41:R41,"X",$P$9:$R$9) -> 3
B42: Fenómenos naturales (sismos, huracanes, etc.) que afectan el cumplimiento en la programación de los módulos de atención ciudadana. | H42: X | I42: =SUMIF(F42:H42, "X",$F$9:$H$9) -> 3 | L42: Realizar convenios con Instituciones competentes para la capacitación del personal en materia registral y de Protección Civil, en Junta Local Ejecutiva, Junta Distrital Ejecutiva y Módulos de Atención Ciudadana. | R42: X | S42: =SUMIF(P42:R42,"X",$P$9:$R$9) -> 3
B43: Falta de disponibilidad inmobiliaria que cumpla con los requisitos legales y físicos para arrendamiento de los Módulos de Atención Ciudadana, Junta local Ejecutiva y Junta Distrital Ejecutiva. | H43: X | I43: =SUMIF(F43:H43, "X",$F$9:$H$9) -> 3 | L43: La posibilidad legal de que Ciudadanos mexicanos residentes en el extranjero puedan emitir su voto para diversos cargos. | R43: X | S43: =SUMIF(P43:R43,"X",$P$9:$R$9) -> 3
B44: Incumplimiento de las empresas prestadoras de servicios para la distribución de credenciales para votar a los Módulos de Atención Ciudadana. | H44: X | I44: =SUMIF(F44:H44, "X",$F$9:$H$9) -> 3 | L44: Certificar los procesos de Módulos de Atención Ciudadana en ISO 9001:2015. | R44: X | S44: =SUMIF(P44:R44,"X",$P$9:$R$9) -> 3
I45: =SUMIF(F45:H45, "X",$F$9:$H$9) -> 0 | L45: Aprovechar las TIC´s para actualizar y depurar el padrón electoral. | R45: x | S45: =SUMIF(P45:R45,"X",$P$9:$R$9) -> 3
I46: =SUMIF(F46:H46, "X",$F$9:$H$9) -> 0 | L46: Aprovechar la infraestructura tecnológica para: Implementar citas programadas en Módulos de Atención Ciudadana itinerantes y medir la satisfacción de la ciudadanía por medio de las boletas electrónicas en Módulos de Atención Ciudadana fijos. | R46: X | S46: =SUMIF(P46:R46,"X",$P$9:$R$9) -> 3
B47: TOTAL | I47: =SUM(I35:I46)*-1 -> -30 | J47: =I47*-1 -> 30 | L47: TOTAL | S47: =SUM(S35:S46) -> 33 | T47: =S47 -> 33 | U47: =(S47*$K$53)/$M$53 -> 6 | W47: =(I47*$K$54)/$M$54 -> -10.285714
B50: Parámetros de análisis situacional de la Organización: | L50: COORDENADAS (EJES)
B51: 1. Fortalezas y Debilidades: | D51: 2. Amenazas y Oportunidades | L51: X | M51: Valor proporcional D + O | N51: =O51 -> 0.90909091 | O51: =U47+U24 -> 0.90909091
B52: a) Dar 1 punto por cada X en desacuerdo | D52: a) Dar 1 punto por cada X bajo No | L52: Y | M52: Valor proporcional F + A | N52: =O52 -> 1.7142857 | O52: =W24+W47 -> 1.7142857
...

Sheet 2b. Matriz Posicionamiento
J1: INSTITUTO NACIONAL ELECTORAL | BL1: Versión: 0
J3: JUNTA LOCAL EJECUTIVA DE NAYARIT | BL3: Fecha de emisión:
J5: FODA | BL5: 43854
AB9: PERFIL: | AC9: =IF(AND(AND(AU34>=0,AU35>=0),AND(AU34<=3,AU35<=6)),"A",IF(AND(AND(AU34>=0,AU35>6),AND(AU34<=3,AU35<=12)),"D",IF(AND(AND(AU34>3,AU35>=0),AND(AU34<=6,AU35<=6)),"B",IF(AND(AND(AU34>3,AU35>6),AND(AU34<=6,AU35<=12)),"C",IF(AND(AND(AU34>=0,AU35<0),AND(AU34<=3,AU35>=-6)),"A",IF(AND(AND(AU34>=0,AU35<-6),AND(AU34<=3,AU35>=-12)),"D",IF(AND(AND(AU34>3,AU35<0),AND(AU34<=6,AU35>=-6)),"B",IF(AND(AND(AU34>3,AU35<-6),AND(AU34<=6,AU35>=-12)),"C",IF(AND(AND(AU34<0,AU35>0),AND(AU34>=-3,AU35<=6)),"A",IF(AND(AND(AU34<-3,AU35>0),AND(AU34>=-6,AU35<=6)),"B",IF(AND(AND(AU34<-3,AU35>6),AND(AU34>=-6,AU35<=12)),"C",IF(AND(AND(AU34<0,AU35>6),AND(AU34>=-3,AU35<=12)),"D",IF(AND(AND(AU34<0,AU35<0),AND(AU34>=-3,AU35>=-6)),"A",IF(AND(AND(AU34<-3,AU35<0),AND(AU34>=-6,AU35>=-6)),"B",IF(AND(AND(AU34<-3,AU35<-6),AND(AU34>=-6,AU35>=-12)),"C",IF(AND(AND(AU34<0,AU35<-6),AND(AU34>=-3,AU35>=-12)),"D","error")))))))))))))))) -> A | AU9: =IF(AND(AND(AU34>=0,AU35>=0),AND(AU34<=6,AU35<=12)),"Perfil Agresivo",IF(AND(AND(AU34<0,AU35>=0),AND(AU34>=-6,AU35<=12)),"Perfil Re Orientación",IF(AND(AND(AU34<0,AU35<0),AND(AU34>=-6,AU35>=-12)),"Perfil Defensivo",IF(AND(AND(AU34>=0,AU35<0),AND(AU34<=6,AU35>=-12)),"Perfil Supervivencia","Error")))) -> Perfil Agresivo
AB10: DEFINICIÓN DEL PERFIL
E11: Perfil Re Orientación | N11: Y | R11: Perfil Agresivo
AB12: Premisa del Perfil | AU12: Definición
AB13: =VLOOKUP(BR15,Perfiles!C3:D18,2,FALSE) -> PERFIL A): Institución y Competencia muy estable (zona de confort +). | AU13: =VLOOKUP(AB13,Perfiles!D3:E18,2,FALSE) -> Institución financieramente estable que no ha obtenido ventajas competitivas importantes en una Institución estable. Institución estable en penetración del mercado y desarrollo del servicio. Institución que cumple con los estándares y procesos definidos por conveniencia propia y por la Institución. Institución que demuestra una comunicación estable interna y externamente. Institución de estructura estable y buena capacidad de reorganizar actividades frente a un riesgo. Institución con personal competente y comprometido con una estructura buena en todas sus áreas. Institución con un ambiente laboral bueno. Institución en cuyos niveles de satisfacción al Cliente interno y externo son buenos. Institución con buen nivel de liderazgo y empoderamiento en las diferentes jerarquías de la misma. Institución con soportes internos y/o externos (perteneciente a un Grupo), que apoya a la línea de productos y/o servicios a todas las partes interesadas.
N14: 16
N15: 14 | BR15: =IF(AND(AND(AU34>=0,AU35>=0),AND(AU34<=3,AU35<=6)),"a",IF(AND(AND(AU34>=0,AU35>6),AND(AU34<=3,AU35<=12)),"d",IF(AND(AND(AU34>3,AU35>=0),AND(AU34<=6,AU35<=6)),"b",IF(AND(AND(AU34>3,AU35>6),AND(AU34<=6,AU35<=12)),"c",IF(AND(AND(AU34>=0,AU35<0),AND(AU34<=3,AU35>=-6)),"e",IF(AND(AND(AU34>=0,AU35<-6),AND(AU34<=3,AU35>=-12)),"h",IF(AND(AND(AU34>3,AU35<0),AND(AU34<=6,AU35>=-6)),"f",IF(AND(AND(AU34>3,AU35<-6),AND(AU34<=6,AU35>=-12)),"g",IF(AND(AND(AU34<0,AU35>0),AND(AU34>=-3,AU35<=6)),"i",IF(AND(AND(AU34<-3,AU35>0),AND(AU34>=-6,AU35<=6)),"j",IF(AND(AND(AU34<-3,AU35>6),AND(AU34>=-6,AU35<=12)),"k",IF(AND(AND(AU34<0,AU35>6),AND(AU34>=-3,AU35<=12)),"l",IF(AND(AND(AU34<0,AU35<0),AND(AU34>=-3,AU35>=-6)),"m",IF(AND(AND(AU34<-3,AU35<0),AND(AU34>=-6,AU35>=-6)),"h",IF(AND(AND(AU34<-3,AU35<-6),AND(AU34>=-6,AU35>=-12)),"o",IF(AND(AND(AU34<0,AU35<-6),AND(AU34>=-3,AU35>=-12)),"p","error")))))))))))))))) -> a
N16: 12
N17: 10
N18: 8
N19: 6
N20: 4
N21: 2
C22: X | N22: 0
F23: -18 | G23: -14 | H23: -12 | I23: -10 | J23: -8 | K23: -6 | L23: -4 | M23: -2 | N23: 0 | O23: 0 | P23: 2 | Q23: 4 | R23: 6 | S23: 8 | T23: 10 | U23: 12 | V23: 14 | W23: 16
N24: -2
N25: -4
N26: -6
N27: -8
N28: -10
N29: -12
N30: -14
N31: -16 | AB31: Coordenadas
AB32: EJE
E33: Perfil Defensivo | R33: Perfil Supervivencia | AB33: COORDENADAS (EJES) | AU33: RESULTADOS
AB34: X | AU34: ='2a. Análisis Foda'!N51 -> 0.90909091 | BN34: =AU34*-1 -> -0.90909091
AB35: Y | AU35: ='2a. Análisis Foda'!N52 -> 1.7142857 | BN35: =AU35*-1 -> -1.7142857

Sheet 3a.Matríz de Partes Interesadas
D1: INSTITUTO NACIONAL ELECTORAL JLE NAYARIT | G1: Versión: 0
D3: SISTEMA DE GESTIÓN DE LA CALIDAD | G3: Fecha de emisión:
D5: PLAN ESTRATÉGICO | G5: 43854
B9: Partes Interesadas | C9: Tipo | D9: Necesidades | E9: Seguimiento | F9: Revisión | G9: Expectativas
D10: Requisitos pertinentes | G10: Requisitos deseables a considerar
B11: Personal de la Delegación INE Nayarit | C11: Interna | D11: • Remuneración Económica. • Buen clima Laboral • Información Institucional. • Capacitación • Conocimiento de las funciones de los puestos. | E11: DEA, DOS y Junta Local Ejecutiva | F11: Evaluaciones de competencias | G11: •Contar con los recursos necesarios para realizar el trabajo. •Motivación Institucional. •Buen trato de los jefes inmediatos. •Ambiente incluyente. •Remuneración justa. •Estabilidad laboral.
B12: Dirección de Operación y Seguimiento (DOS). | C12: Interna | D12: • Cumplir con las funciones, actividades y procedimientos para la operación del MAC. • Personal de MAC debidamente capacitado. • Aplicación correcta de las supervisiones a los MAC. • Cumplir con los procedimientos para el retiro, resguardo y destrucción de formatos de credencial de los MAC. • Coordinar la liberación de la plantilla para la operación de los MAC. • Mantener el parque vehicular en buen estado para garantizar la operación del MAC. • Mantener el equipo tecnológico necesario y en buen estado para la operación del MAC. | E12: Juntas Local y Distritales Ejecutivas | F12: • Programa de Capacitación. • Indicadores de desempeño. • Manuales de Operación actualizados. • Cedula de supervisión. • Inventario de infraestructura. | G12: • Las funciones, actividades y procedimientos que se establecen para la operación del Módulo de Atención Ciudadana son comprendidas y aplicadas en su totalidad. • La efectividad de la Capacitación del personal es reflejada en la operación del MAC. • Los procedimientos de seguimiento y evaluación de la operación arrojen los resultados positivos. • Correcta aplicación de los Manuales operativos para la operación de MAC. • Equipo tecnológico, infraestructura, mobiliario y parque vehicular suficientes que se mantengan en buen estado.
B13: Dirección de Depuración y Verificación en Campo (DDVC) | C13: Interna | D13: • Inclusión o exclusión de la Ciudadanía al Padrón Electoral. • Realizar la validación para la presunta usurpación de identidad y datos apócrifos de la ciudadanía. • Investigar los casos de datos presuntamente irregulares de la ciudadanía. • Informar a la ciudadanía la suspensión de sus derechos políticos. • Informar a la ciudadanía la cancelación de su trámite por datos irregulares. • Informar a la ciudadanía sobre posibles domicilios irregulares. | E13: Junta Local Ejecutiva/Depuración al Padrón. | F13: • Base de datos del Padrón Electoral actualizado. • Análisis registral. | G13: • Padrón Electoral actualizado. • Identificación de la ciudadanía que pretende realizar robo de identidad. • Identificación de la ciudadanía con datos usurpados. • Tener actualizada la reincorporación de la ciudadanía con retiro de sus derechos políticos. • Base de datos actualizada hasta la fecha.
B14: Dirección de Cartografía (DCE) | C14: Interna | D14: • Referenciar correctamente el domicilio de la Ciudadanía. • Actualizar la cartografía electoral para el uso de los MAC. | E14: Junta Local Ejecutiva/ Cartografía Estatal | F14: • Formato CIF-05 lleno para verificar las claves geoelectorales. | G14: • La verificación en campo pueda ser localizada fácilmente por el técnico cartográfico y las georreferencias proporcionadas den información veraz de la ubicación de la ciudadanía. • La actualización cartográfica electoral se mantenga actualizada en el menor tiempo posible. • El crecimiento demográfico no sea de forma acelerada.
B15: Dirección de Atención Ciudadana INETEL y Centro de Atención Ciudadana (DAC) | C15: Interna | D15: • Brindar información a la ciudadanía de la documentación requerida para el trámite de credencial. • Informar al ciudadano del status de la su trámite de CPV. • Recibir, canalizar y dar seguimiento a las quejas ciudadanas • Generar cita para el trámite de CPV. • Recibir denuncias por robo y/o extravío de credencial. • Recibir, canalizar y dar seguimiento a quejas y/o denuncias en contra de personal de MAC. | E15: Junta Local Ejecutiva/ CECEOC | F15: • Base de datos del Padrón Electoral • Internet para generar las citas programadas • Sistema Remedy para registrar las atenciones ciudadanas por teléfono y presenciales • SIIRFE Monitoreo Trámites y Credenciales Robadas y Extraviadas | G15: • Brindar la información más oportuna y adecuada para el trámite de credencial. • Atender un gran porcentaje de citas programadas. • Brindar a la ciudadanía los requisitos adecuadamente en los medios de comunicación de la DAC para no recibir quejas. • Dar inmediata respuesta a las quejas presentadas.
B16: Dirección de Ejecutiva Administrativa (DEA) | C16: Interna | D16: • Administrar correctamente los recursos humanos, financieros y materiales para el cumplimiento de las funciones operativas de las vocalías del Registro Federal de Electores. • Llevar acabo la planeación y programación de los recursos financieros, para garantizar la operación y desarrollo de los programas y proyectos de las vocalías del Registro Federal de Electores. | E16: Juntas Local y Distritales Ejecutivas | F16: • Documentos normativos-administrativos, con la finalidad de contribuir al cumplimiento de los programas y proyectos | G16: • Aplicación de los recursos, financieros y materiales para la operación de los MAC ´s. • Buena Integración de los documentos presupuestales de control de la evaluación.
B17: CECyRD | C17: Interna | D17: • Que el flujo de la información de inscripción y actualización sea constante y sin interrupciones. • Validar la información generada en el MAC. • Que se integre la Solicitud individual de inscripción o actualización del ciudadano. • Enviar la información para la credencial para votar. | E17: Juntas Local y Distritales Ejecutivas/Mac 's | F17: • Actualización de las versiones en SIRFE-MAC, permitiendo realizar el levantamiento de tramites en forma correcta. | G17: • Base de datos capturadas correctamente. • Que no existan afectaciones o errores en la base de datos del INE. • Digitalización de la documentación de la ciudadanía sea correcta. • Que la operación no sea interrumpido por falta de insumos. • Todas las validaciones, solicitudes, inscripciones envío y recibo de información son adecuadas.
B18: Instituciones Privadas | C18: Externa | D18: • Contar con un instrumento confiable de identificación ciudadana que le permita ser fuente confiable para otorgar servicios a sus clientes | E18: Consejo General/ Junta General Ejecutiva | F18: •Convenios de apoyo y colaboración. | G18: •Que los ciudadanos cuenten con una identificación vigente. •Prevención de falsificaciones de la CPV. • Que la Información sea fidedigna de la identificación otorgada por el Instituto de acuerdo con los requisitos establecidos.
B19: Instituciones Públicas (Federales y Estatales) | C19: Externa | D19: • Que se aplique lo estipulado en la constitución política mexicana y leyes reglamentarias, así como convenios que se establezcan con el Instituto | E19: Juntas Local y Distritales Ejecutivas/Mac 's | F19: •Convenios de apoyo y colaboración. | G19: •Información oportuna y certera de la información contenida en los instrumentos electorales a cargo del instituto.
B20: Proveedores | C20: Externa | D20: • Pago oportuno • Negocio permanente | E20: Jefe de Recursos Materiales./Junta Local Ejecutiva. | F20: •Evaluaciones de proveedores | G20: • Política de entregas. •Créditos.
B21: Ciudadanía | C21: Externa | D21: • Obtener un documento oficial que permite la identidad de la ciudadanía. • Recibir información clara y precisa para el trámite de credencial. • Obtener orientación de los requisitos que deben cumplir sus documentos para el trámite. • No tener errores en la impresión de la Credencial para Votar • Ser atendidos con cordialidad y respeto sin discriminación por parte del personal. | E21: Juntas Local y Distritales Ejecutivas | F21: • Credencial para Votar | G21: • Que se realice el trámite conforme a la normatividad. • Atención y seguimiento a quejas. • Entrega de Credencial para votar a la ciudadanía.
B22: Medios de comunicación | C22: Externa | D22: • La información proporcionada por la institución se realice de manera oportuna y verídica conforme a los tramites que se realizan en los MAC 's | E22: Juntas Local y Distritales Ejecutivas | F22: • Que los anuncios del INE sean trasmitidos a la ciudadanía en radio, televisión, redes sociales. | G22: • Que la información sea compartida de forma inmediata y directa con los medios de comunicación.
... B24: Partidos Políticos | C24: Externa | D24: • Que la ciudadanía pueda obtener su CPV para ejercer su derecho al voto. | E24: Juntas Local y Distritales Ejecutivas/Órganos de Vigilancia | F24: • Con los informes de los Órganos de Vigilancia, a través de las sesiones que se desarrollan en dichos órganos. | G24: • Contar con la un Padrón y Lista Nominal de Electores confiable en la que no existan duplicidades y depurado. • Que el nivel de cobertura permita asegurar el derecho del voto de la ciudadanía.

Sheet 4a. Parámetros de riesgo
E1: INSTITUTO NACIONAL ELECTORAL JLE NAYARIT | L1: Versión: 0
E3: SISTEMA DE GESTIÓN DE LA CALIDAD | L3: Fecha de emisión:
E5: PLAN ESTRATÉGICO | L5: 43854
B8: RIESGOS | H8: OPORTUNIDADES
B9: NATURALEZA | C9: DEFINICIONES | H9: NATURALEZA | I9: DEFINICIONES
B10: Operativa | C10: Riesgo cuyos efectos están relacionados con la nula o mala prestación del servicio y/o entrega de la credencial para votar durante la operación y a la entrega a la Ciudadanía. Puede incluir maquinaria, equipo, infraestructura, recurso humano, insumos, servicios de apoyo (agua potable, electricidad, redes, internet, Sistema SIIRFE-MAC) y partes interesadas. | H10: Operativa | I10: Oportunidad cuyos efectos están relacionados con la prestación del servicio y/o entrega de la credencial para votar durante la operación y a la entrega a la Ciudadanía de forma eficiente. Puede incluir maquinaria, equipo, infraestructura, recurso humano, insumos, servicios de apoyo (agua potable, electricidad, redes, internet, Sistema SIIRFE-MAC, etc.) y partes interesadas.
B11: Ambiental | C11: Cualquier riesgo cuyo efecto negativo está relacionado con la salud física, medio ambiente y seguridad laboral de cualquier parte interesada (interna o externa) así como el ambiente laboral de los funcionarios dentro de la Delegación INE Nayarit. | H11: Ambiental | I11: Oportunidad cuyo efecto está relacionado con mantener e incrementar los beneficios en la salud física, medio ambiente y seguridad laboral de cualquier parte interesada (interna y externa) así como el ambiente laboral de los funcionarios dentro de la Delegación INE Nayarit.
B12: Legal y Reglamentario | C12: Riesgo cuyos efectos están relacionados con los cambios de las normatividades legales y reglamentarias aplicables a la Delegación INE Nayarit en el ámbito federal, local y del ramo que no permitan acceder, mantener o mejorar las relaciones con las partes interesadas y esto afecte a la Delegación INE Nayarit durante la operación y a la entrega de la credencial para votar y/o trámite a la Ciudadanía. | H12: Legal y Reglamentario | I12: Oportunidad cuyos efectos están relacionados con el aprovechamiento de los cambios en las normatividades legales y reglamentarias aplicables a la Delegación INE Nayarit en el ámbito federal, local y del ramo que permitan mantener y mejorar las relaciones con las partes interesadas durante la operación y a la entrega de la credencial para votar y/o trámite a la Ciudadanía.
B13: Política | C13: Riesgo cuyos efectos están relacionados con la probabilidad de que las fuerzas políticas generen cambios negativos en el entorno de la Delegación INE Nayarit y obstaculicen o minimicen relaciones con partes interesadas. | H13: Política | I13: Oportunidad cuyos efectos están relacionados con la probabilidad de que las fuerzas políticas generen cambios positivos en el entorno de la Delegación INE Nayarit y apoyen a mejorar las relaciones con las partes interesadas.
B14: Industrial | C14: Riesgo cuyos efectos están relacionados con partes interesadas que generan una desventaja frente a la competencia en el mismo ramo, zona geográfica, Ciudad, Estado y/o País en la prestación del producto / servicio brindado a la Ciudadanía. | H14: Industrial | I14: Oportunidad cuyos efectos están relacionados con partes interesadas que generan una ventaja competitiva en el mismo ramo, zona geográfica, Ciudad, Estado y/o País en la prestación del producto / servicio brindado a la Ciudadanía.
B15: Institucional | C15: Riesgo cuyos efectos están relacionados con cambios en la planeación y ejecución estratégica del INE, DERFE, DOS que provocan limitantes tangibles e intangibles en los resultados de la Delegación INE Nayarit. | H15: Institucional | I15: Oportunidad cuyos efectos están relacionados con cambios en la planeación y ejecución estratégica del INE, DERFE, DOS que provocan beneficios tangibles e intangibles en los resultados de la Delegación INE Nayarit.
B16: Social/Cultural | C16: Riesgo en los integrantes del mercado y su influencia en el entorno. Variables como la evolución demográfica, movilidad social, cambios en el estilo de vida, actitud consumista, nivel educativo, patrones culturales y la religión. | H16: Social/Cultural | I16: Oportunidad que los integrantes del mercado y su influencia en el entorno sean de beneficio con la evolución demográfica, movilidad social, cambios en el estilo de vida, actitud consumista, nivel educativo, patrones culturales y la religión.
B17: Tecnológicos | C17: Riesgo del desarrollo tecnológico y sus aportes en la actividad Institucional. Depende de su estado la cifra en gasto público en investigación, preocupación gubernamental y de industria por la tecnología, grado de obsolescencia, madurez de las tecnologías convencionales, desarrollo de nuevos productos, velocidad de transmisión de la tecnología | H17: Tecnológicos | I17: Oportunidad en el desarrollo tecnológico y sus aportes en la actividad de la Delegación INE Nayarit, madurez de las tecnologías convencionales, desarrollo de nuevos productos, velocidad de transmisión de la tecnología
B18: Económico / Financiero | C18: Riesgo cuyos efectos están relacionados con limitar o detener la sostenibilidad financiera de la Delegación INE Nayarit las cuales pueden ser generadas en conjunto por una o unas de las partes interesadas. | H18: Económico / Financiero | I18: Oportunidad cuyos efectos están relacionados con mantener e incrementar la sostenibilidad financiera de la Delegación INE Nayarit las cuales pueden ser generadas en conjunto por una o unas de las partes interesadas.
B20: OCURRENCIA | C20: DEFINICIONES | H20: OCURRENCIA | I20: DEFINICIONES
B21: Baja | C21: Remotamente posible. El daño ocurre muy rara vez. | H21: Baja | I21: Remotamente posible. La oportunidad ocurre muy rara vez.
... B28: Grave | C28: Riesgo negativo que afecta gravemente la integridad para otorgar la prestación del producto / servicio determinado por la Delegación INE Nayarit. Pocas veces puede revertirse en un mediano o largo tiempo y genera costos de no calidad altos y con daños visiblemente permanentes. | H28: Importante | I28: Impacto positivo garantizado que potencializa la integridad para otorgar la prestación del producto / servicio determinado por la Delegación INE Nayarit. Puede implementarse en un mediano o largo tiempo y genera costos de calidad considerables y posiblemente permanentes.
B30: RANGOS | C30: CLASIFICACIÓN | D30: DICTAMEN | E30: ACCIONES | H30: RANGOS | I30: CLASIFICACIÓN | J30: DICTAMEN | K30: ACCIONES
B31: 0 - 199 | C31: TRIVIAL | D31: VIGILARLO | E31: Control rutinario, no afecta la secuencia e integridad de los procesos de una o varias áreas de la Delegación INE Nayarit, el SGC y/o partes interesadas. | H31: 0 - 250 | I31: LIMITADA | J31: A CONSIDERAR | K31: Oportunidad que genera un beneficio mínimo en los procesos de una o varias áreas de la Institución, el SGC y/o Partes Interesadas de la cual se espera un resultado inmediato.
B32: 200 - 399 | C32: TOLERABLE | D32: ASUMIRLO | E32: Monitorear el riesgo, afecta mínimamente la secuencia y la integridad de los procesos de una o varias áreas de la Delegación INE Nayarit, el SGC y/opartes interesadas. | H32: 251 - 500 | I32: MEDIA | J32: ABORDAR | K32: Oportunidad con buena posibilidad de abordarse siempre y cuando se profundice en los beneficios esperados en los procesos de una o varias áreas de la Delegación INE Nayarit, el SGC y/o Partes Interesadas de la cual se espera un resultado a corto plazo.
B33: 400 - 599 | C33: MODERADO | D33: CONTROLARLO | E33: Plan de acción eficaz donde se realice un control permanente ya que existe un riesgo moderado en la secuencia y la integridad de los procesos de una o varias áreas de la Delegación INE Nayarit, al SGC y/o partes interesadas. | H33: 501 - 750 | I33: POTENCIAL | J33: APROPIARSE | K33: Oportunidad con beneficios claros y específicos en los procesos de una o varias áreas de la Delegación INE Nayarit, el SGC y/o Partes Interesadas, de la cual se espera un resultado a corto y mediano plazo.
B34: 600 - 799 | C34: IMPORTANTE | D34: MINIMIZARLO | E34: Acción de contención inmediata, es importante generar un plan de acción eficaz y eficiente donde se realice un control específico y permanente ya que el riesgo es alto en la secuencia y la integridad de los procesos de varias áreas de la Delegación INE Nayarit, el SGC y/o partes interesadas. | H34: 751 - 1000 | I34: SOBRESALIENTE | J34: EXPLOTARLA | K34: Oportunidad con beneficios claros, generales y específicos en los procesos de varias o todas las áreas de la Delegación INE Nayarit, el SGC y/o Partes Interesadas de la cual se obtiene un resultado a corto, mediano y/o largo plazo.
B35: 800 - 1000 | C35: INTOLERABLE | D35: ATENCIÓN INMEDIATA | E35: Acción de contención inmediata, es urgente generar un plan de acción y revisión del proceso (aplicar reingeniería si es necesario) eficaz y eficiente donde se realice un control específico y permanente ya que el riesgo es grave en la secuencia y la integridad de los procesos de varias o todas las áreas de la Delegación INE Nayarit, el SGC y/o partes interesadas.

Sheet 4b. Matriz - Contexto
D2: INSTITUTO NACIONAL ELECTORAL JLE NAYARIT | T2: Versión: 0
D4: SISTEMA DE GESTIÓN DE LA CALIDAD | T4: Fecha de emisión:
D6: PLAN ESTRATÉGICO | T6: 43854
B9: CLASIFICACIÓN DEL FODA | C9: DESCRIPCIÓN DEL RIESGO / OPORTUNIDAD GENERAL | D9: TIPO DE EFECTO | E9: PROCESOS AFECTADOS / BENEFICIADOS | P9: NATURALEZA | Q9: OCURRENCIA | R9: SEVERIDAD | S9: NIVEL DE RIESGO / OPORTUNIDAD | T9: CLASIFICACIÓN | U9: DICTAMEN | V9: CONCLUSIONES
E10: Entrevista | F10: Trámite | G10: Transferencia | H10: Conciliación | I10: Entrega de Credencial | J10: Reclutamiento y Selección | K10: Capacitación | L10: Desempeño de Personal | M10: Soporte Técnico | N10: Bienes y Servicios | O10: Alta Dirección
B11: Fortaleza | C11: ='2a. Análisis Foda'!B10:B10 -> Se tiene una planeación de Directorio de Módulos. | D11: Positivo | S11: =IFERROR(VLOOKUP(P11,Naturaleza,2,FALSE)*VLOOKUP('4b. Matriz - Contexto'!Q11,Probabilidad,2,FALSE)*VLOOKUP('4b. Matriz - Contexto'!R11,Severidad,2,FALSE),"") | T11: =IF(B11="Debilidad",IF(S11="","",IF(AND(S11>0,S11<200),"Trivial",IF(OR(S11=200,AND(S11>200,S11<400)),"Tolerable",IF(OR(S11=400,AND(S11>400,S11<600)),"Moderado",IF(OR(S11=600,AND(S11>600,S11<800)),"Importante",IF(OR(S11=800,S11>800,S11<1000,S11=1000),"Intolerable","")))))),IF(B11="Amenaza",IF(S11="","",IF(AND(S11>0,S11<200),"Trivial",IF(OR(S11=200,AND(S11>200,S11<400)),"Tolerable",IF(OR(S11=400,AND(S11>400,S11<600)),"Moderado",IF(OR(S11=600,AND(S11>600,S11<800)),"Importante",IF(OR(S11=800,S11>800,S11<1000,S11=1000),"Intolerable","")))))),IF(B11="Fortaleza",IF(S11="","",IF(AND(S11>0,S11<250),"Limitada",IF(OR(S11=250,AND(S11>250,S11<500)),"Media",IF(OR(S11=500,AND(S11>500,S11<750)),"Potencial",IF(OR(S11=750,AND(S11>750,S11<=1000)),"Sobresaliente", ""))))), IF(B11="Oportunidad",IF(S11="","",IF(AND(S11>0,S11<250),"Limitada",IF(OR(S11=250,AND(S11>250,S11<500)),"Media",IF(OR(S11=500,AND(S11>500,S11<750)),"Potencial",IF(OR(S11=750,AND(S11>750,S11<=1000)),"Sobresaliente",""))))),"")))) | U11: =IFERROR(VLOOKUP(T11,'4a. Parámetros de riesgo'!$C$31:$D$35,2,FALSE),IFERROR(VLOOKUP(T11,'4a. Parámetros de riesgo'!$I$31:$J$35,2,FALSE),"")) | V11: =IFERROR(VLOOKUP(U11,'4a. Parámetros de riesgo'!$D$31:$E$35,2,FALSE),IFERROR(VLOOKUP(U11,'4a. Parámetros de riesgo'!$J$31:$K$35,2,FALSE),""))
B12: Fortaleza | C12: ='2a. Análisis Foda'!B11:B11 -> Atención a Ciudadanos con problemas de movilización. | D12: Positivo | S12: =IFERROR(VLOOKUP(P12,Naturaleza,2,FALSE)*VLOOKUP('4b. Matriz - Contexto'!Q12,Probabilidad,2,FALSE)*VLOOKUP('4b. Matriz - Contexto'!R12,Severidad,2,FALSE),"") | T12: =IF(B12="Debilidad",IF(S12="","",IF(AND(S12>0,S12<200),"Trivial",IF(OR(S12=200,AND(S12>200,S12<400)),"Tolerable",IF(OR(S12=400,AND(S12>400,S12<600)),"Moderado",IF(OR(S12=600,AND(S12>600,S12<800)),"Importante",IF(OR(S12=800,S12>800,S12<1000,S12=1000),"Intolerable","")))))),IF(B12="Amenaza",IF(S12="","",IF(AND(S12>0,S12<200),"Trivial",IF(OR(S12=200,AND(S12>200,S12<400)),"Tolerable",IF(OR(S12=400,AND(S12>400,S12<600)),"Moderado",IF(OR(S12=600,AND(S12>600,S12<800)),"Importante",IF(OR(S12=800,S12>800,S12<1000,S12=1000),"Intolerable","")))))),IF(B12="Fortaleza",IF(S12="","",IF(AND(S12>0,S12<250),"Limitada",IF(OR(S12=250,AND(S12>250,S12<500)),"Media",IF(OR(S12=500,AND(S12>500,S12<750)),"Potencial",IF(OR(S12=750,AND(S12>750,S12<=1000)),"Sobresaliente", ""))))), IF(B12="Oportunidad",IF(S12="","",IF(AND(S12>0,S12<250),"Limitada",IF(OR(S12=250,AND(S12>250,S12<500)),"Media",IF(OR(S12=500,AND(S12>500,S12<750)),"Potencial",IF(OR(S12=750,AND(S12>750,S12<=1000)),"Sobresaliente",""))))),"")))) | U12: =IFERROR(VLOOKUP(T12,'4a. Parámetros de riesgo'!$C$31:$D$35,2,FALSE),IFERROR(VLOOKUP(T12,'4a. Parámetros de riesgo'!$I$31:$J$35,2,FALSE),"")) | V12: =IFERROR(VLOOKUP(U12,'4a. Parámetros de riesgo'!$D$31:$E$35,2,FALSE),IFERROR(VLOOKUP(U12,'4a. Parámetros de riesgo'!$J$31:$K$35,2,FALSE),""))
B13: Fortaleza | C13: ='2a. Análisis Foda'!B12:B12 -> Compromiso institucional de la Alta Dirección del Instituto. | D13: Positivo | S13: =IFERROR(VLOOKUP(P13,Naturaleza,2,FALSE)*VLOOKUP('4b. Matriz - Contexto'!Q13,Probabilidad,2,FALSE)*VLOOKUP('4b. Matriz - Contexto'!R13,Severidad,2,FALSE),"") | T13: =IF(B13="Debilidad",IF(S13="","",IF(AND(S13>0,S13<200),"Trivial",IF(OR(S13=200,AND(S13>200,S13<400)),"Tolerable",IF(OR(S13=400,AND(S13>400,S13<600)),"Moderado",IF(OR(S13=600,AND(S13>600,S13<800)),"Importante",IF(OR(S13=800,S13>800,S13<1000,S13=1000),"Intolerable","")))))),IF(B13="Amenaza",IF(S13="","",IF(AND(S13>0,S13<200),"Trivial",IF(OR(S13=200,AND(S13>200,S13<400)),"Tolerable",IF(OR(S13=400,AND(S13>400,S13<600)),"Moderado",IF(OR(S13=600,AND(S13>600,S13<800)),"Importante",IF(OR(S13=800,S13>800,S13<1000,S13=1000),"Intolerable","")))))),IF(B13="Fortaleza",IF(S13="","",IF(AND(S13>0,S13<250),"Limitada",IF(OR(S13=250,AND(S13>250,S13<500)),"Media",IF(OR(S13=500,AND(S13>500,S13<750)),"Potencial",IF(OR(S13=750,AND(S13>750,S13<=1000)),"Sobresaliente", ""))))), IF(B13="Oportunidad",IF(S13="","",IF(AND(S13>0,S13<250),"Limitada",IF(OR(S13=250,AND(S13>250,S13<500)),"Media",IF(OR(S13=500,AND(S13>500,S13<750)),"Potencial",IF(OR(S13=750,AND(S13>750,S13<=1000)),"Sobresaliente",""))))),"")))) | U13: =IFERROR(VLOOKUP(T13,'4a. Parámetros de riesgo'!$C$31:$D$35,2,FALSE),IFERROR(VLOOKUP(T13,'4a. Parámetros de riesgo'!$I$31:$J$35,2,FALSE),"")) | V13: =IFERROR(VLOOKUP(U13,'4a. Parámetros de riesgo'!$D$31:$E$35,2,FALSE),IFERROR(VLOOKUP(U13,'4a. Parámetros de riesgo'!$J$31:$K$35,2,FALSE),""))
B14: Fortaleza | C14: ='2a. Análisis Foda'!B13:B13 -> Personal experimentado en Módulos de Atención Ciudadana. | D14: Positivo | S14: =IFERROR(VLOOKUP(P14,Naturaleza,2,FALSE)*VLOOKUP('4b. Matriz - Contexto'!Q14,Probabilidad,2,FALSE)*VLOOKUP('4b. Matriz - Contexto'!R14,Severidad,2,FALSE),"") | T14: =IF(B14="Debilidad",IF(S14="","",IF(AND(S14>0,S14<200),"Trivial",IF(OR(S14=200,AND(S14>200,S14<400)),"Tolerable",IF(OR(S14=400,AND(S14>400,S14<600)),"Moderado",IF(OR(S14=600,AND(S14>600,S14<800)),"Importante",IF(OR(S14=800,S14>800,S14<1000,S14=1000),"Intolerable","")))))),IF(B14="Amenaza",IF(S14="","",IF(AND(S14>0,S14<200),"Trivial",IF(OR(S14=200,AND(S14>200,S14<400)),"Tolerable",IF(OR(S14=400,AND(S14>400,S14<600)),"Moderado",IF(OR(S14=600,AND(S14>600,S14<800)),"Importante",IF(OR(S14=800,S14>800,S14<1000,S14=1000),"Intolerable","")))))),IF(B14="Fortaleza",IF(S14="","",IF(AND(S14>0,S14<250),"Limitada",IF(OR(S14=250,AND(S14>250,S14<500)),"Media",IF(OR(S14=500,AND(S14>500,S14<750)),"Potencial",IF(OR(S14=750,AND(S14>750,S14<=1000)),"Sobresaliente", ""))))), IF(B14="Oportunidad",IF(S14="","",IF(AND(S14>0,S14<250),"Limitada",IF(OR(S14=250,AND(S14>250,S14<500)),"Media",IF(OR(S14=500,AND(S14>500,S14<750)),"Potencial",IF(OR(S14=750,AND(S14>750,S14<=1000)),"Sobresaliente",""))))),"")))) | U14: =IFERROR(VLOOKUP(T14,'4a. Parámetros de riesgo'!$C$31:$D$35,2,FALSE),IFERROR(VLOOKUP(T14,'4a. Parámetros de riesgo'!$I$31:$J$35,2,FALSE),"")) | V14: =IFERROR(VLOOKUP(U14,'4a. Parámetros de riesgo'!$D$31:$E$35,2,FALSE),IFERROR(VLOOKUP(U14,'4a. Parámetros de riesgo'!$J$31:$K$35,2,FALSE),""))
B15: Fortaleza | C15: ='2a. Análisis Foda'!B14:B14 -> Procedimientos estandarizados en manuales y lineamientos. | D15: Positivo | S15: =IFERROR(VLOOKUP(P15,Naturaleza,2,FALSE)*VLOOKUP('4b. Matriz - Contexto'!Q15,Probabilidad,2,FALSE)*VLOOKUP('4b. Matriz - Contexto'!R15,Severidad,2,FALSE),"") | T15: =IF(B15="Debilidad",IF(S15="","",IF(AND(S15>0,S15<200),"Trivial",IF(OR(S15=200,AND(S15>200,S15<400)),"Tolerable",IF(OR(S15=400,AND(S15>400,S15<600)),"Moderado",IF(OR(S15=600,AND(S15>600,S15<800)),"Importante",IF(OR(S15=800,S15>800,S15<1000,S15=1000),"Intolerable","")))))),IF(B15="Amenaza",IF(S15="","",IF(AND(S15>0,S15<200),"Trivial",IF(OR(S15=200,AND(S15>200,S15<400)),"Tolerable",IF(OR(S15=400,AND(S15>400,S15<600)),"Moderado",IF(OR(S15=600,AND(S15>600,S15<800)),"Importante",IF(OR(S15=800,S15>800,S15<1000,S15=1000),"Intolerable","")))))),IF(B15="Fortaleza",IF(S15="","",IF(AND(S15>0,S15<250),"Limitada",IF(OR(S15=250,AND(S15>250,S15<500)),"Media",IF(OR(S15=500,AND(S15>500,S15<750)),"Potencial",IF(OR(S15=750,AND(S15>750,S15<=1000)),"Sobresaliente", ""))))), IF(B15="Oportunidad",IF(S15="","",IF(AND(S15>0,S15<250),"Limitada",IF(OR(S15=250,AND(S15>250,S15<500)),"Media",IF(OR(S15=500,AND(S15>500,S15<750)),"Potencial",IF(OR(S15=750,AND(S15>750,S15<=1000)),"Sobresaliente",""))))),"")))) | U15: =IFERROR(VLOOKUP(T15,'4a. Parámetros de riesgo'!$C$31:$D$35,2,FALSE),IFERROR(VLOOKUP(T15,'4a. Parámetros de riesgo'!$I$31:$J$35,2,FALSE),"")) | V15: =IFERROR(VLOOKUP(U15,'4a. Parámetros de riesgo'!$D$31:$E$35,2,FALSE),IFERROR(VLOOKUP(U15,'4a. Parámetros de riesgo'!$J$31:$K$35,2,FALSE),""))
B16: Fortaleza | C16: ='2a. Análisis Foda'!B15:B15 -> Conocimiento de la normatividad por parte del personal. | D16: Positivo | S16: =IFERROR(VLOOKUP(P16,Naturaleza,2,FALSE)*VLOOKUP('4b. Matriz - Contexto'!Q16,Probabilidad,2,FALSE)*VLOOKUP('4b. Matriz - Contexto'!R16,Severidad,2,FALSE),"") | T16: =IF(B16="Debilidad",IF(S16="","",IF(AND(S16>0,S16<200),"Trivial",IF(OR(S16=200,AND(S16>200,S16<400)),"Tolerable",IF(OR(S16=400,AND(S16>400,S16<600)),"Moderado",IF(OR(S16=600,AND(S16>600,S16<800)),"Importante",IF(OR(S16=800,S16>800,S16<1000,S16=1000),"Intolerable","")))))),IF(B16="Amenaza",IF(S16="","",IF(AND(S16>0,S16<200),"Trivial",IF(OR(S16=200,AND(S16>200,S16<400)),"Tolerable",IF(OR(S16=400,AND(S16>400,S16<600)),"Moderado",IF(OR(S16=600,AND(S16>600,S16<800)),"Importante",IF(OR(S16=800,S16>800,S16<1000,S16=1000),"Intolerable","")))))),IF(B16="Fortaleza",IF(S16="","",IF(AND(S16>0,S16<250),"Limitada",IF(OR(S16=250,AND(S16>250,S16<500)),"Media",IF(OR(S16=500,AND(S16>500,S16<750)),"Potencial",IF(OR(S16=750,AND(S16>750,S16<=1000)),"Sobresaliente", ""))))), IF(B16="Oportunidad",IF(S16="","",IF(AND(S16>0,S16<250),"Limitada",IF(OR(S16=250,AND(S16>250,S16<500)),"Media",IF(OR(S16=500,AND(S16>500,S16<750)),"Potencial",IF(OR(S16=750,AND(S16>750,S16<=1000)),"Sobresaliente",""))))),"")))) | U16: =IFERROR(VLOOKUP(T16,'4a. Parámetros de riesgo'!$C$31:$D$35,2,FALSE),IFERROR(VLOOKUP(T16,'4a. Parámetros de riesgo'!$I$31:$J$35,2,FALSE),"")) | V16: =IFERROR(VLOOKUP(U16,'4a. Parámetros de riesgo'!$D$31:$E$35,2,FALSE),IFERROR(VLOOKUP(U16,'4a. Parámetros de riesgo'!$J$31:$K$35,2,FALSE),""))
B17: Fortaleza | C17: ='2a. Análisis Foda'!B16:B16 -> Fideicomiso para la infraestructura de Módulos de Atención Ciudadana. | D17: Positivo | S17: =IFERROR(VLOOKUP(P17,Naturaleza,2,FALSE)*VLOOKUP('4b. Matriz - Contexto'!Q17,Probabilidad,2,FALSE)*VLOOKUP('4b. Matriz - Contexto'!R17,Severidad,2,FALSE),"") | T17: =IF(B17="Debilidad",IF(S17="","",IF(AND(S17>0,S17<200),"Trivial",IF(OR(S17=200,AND(S17>200,S17<400)),"Tolerable",IF(OR(S17=400,AND(S17>400,S17<600)),"Moderado",IF(OR(S17=600,AND(S17>600,S17<800)),"Importante",IF(OR(S17=800,S17>800,S17<1000,S17=1000),"Intolerable","")))))),IF(B17="Amenaza",IF(S17="","",IF(AND(S17>0,S17<200),"Trivial",IF(OR(S17=200,AND(S17>200,S17<400)),"Tolerable",IF(OR(S17=400,AND(S17>400,S17<600)),"Moderado",IF(OR(S17=600,AND(S17>600,S17<800)),"Importante",IF(OR(S17=800,S17>800,S17<1000,S17=1000),"Intolerable","")))))),IF(B17="Fortaleza",IF(S17="","",IF(AND(S17>0,S17<250),"Limitada",IF(OR(S17=250,AND(S17>250,S17<500)),"Media",IF(OR(S17=500,AND(S17>500,S17<750)),"Potencial",IF(OR(S17=750,AND(S17>750,S17<=1000)),"Sobresaliente", ""))))), IF(B17="Oportunidad",IF(S17="","",IF(AND(S17>0,S17<250),"Limitada",IF(OR(S17=250,AND(S17>250,S17<500)),"Media",IF(OR(S17=500,AND(S17>500,S17<750)),"Potencial",IF(OR(S17=750,AND(S17>750,S17<=1000)),"Sobresaliente",""))))),"")))) | U17: =IFERROR(VLOOKUP(T17,'4a. Parámetros de riesgo'!$C$31:$D$35,2,FALSE),IFERROR(VLOOKUP(T17,'4a. Parámetros de riesgo'!$I$31:$J$35,2,FALSE),"")) | V17: =IFERROR(VLOOKUP(U17,'4a. Parámetros de riesgo'!$D$31:$E$35,2,FALSE),IFERROR(VLOOKUP(U17,'4a. Parámetros de riesgo'!$J$31:$K$35,2,FALSE),""))
B18: Fortaleza | C18: ='2a. Análisis Foda'!B17:B17 -> Profesionalización de los MSPEN . | D18: Positivo | S18: =IFERROR(VLOOKUP(P18,Naturaleza,2,FALSE)*VLOOKUP('4b. Matriz - Contexto'!Q18,Probabilidad,2,FALSE)*VLOOKUP('4b. Matriz - Contexto'!R18,Severidad,2,FALSE),"") | T18: =IF(B18="Debilidad",IF(S18="","",IF(AND(S18>0,S18<200),"Trivial",IF(OR(S18=200,AND(S18>200,S18<400)),"Tolerable",IF(OR(S18=400,AND(S18>400,S18<600)),"Moderado",IF(OR(S18=600,AND(S18>600,S18<800)),"Importante",IF(OR(S18=800,S18>800,S18<1000,S18=1000),"Intolerable","")))))),IF(B18="Amenaza",IF(S18="","",IF(AND(S18>0,S18<200),"Trivial",IF(OR(S18=200,AND(S18>200,S18<400)),"Tolerable",IF(OR(S18=400,AND(S18>400,S18<600)),"Moderado",IF(OR(S18=600,AND(S18>600,S18<800)),"Importante",IF(OR(S18=800,S18>800,S18<1000,S18=1000),"Intolerable","")))))),IF(B18="Fortaleza",IF(S18="","",IF(AND(S18>0,S18<250),"Limitada",IF(OR(S18=250,AND(S18>250,S18<500)),"Media",IF(OR(S18=500,AND(S18>500,S18<750)),"Potencial",IF(OR(S18=750,AND(S18>750,S18<=1000)),"Sobresaliente", ""))))), IF(B18="Oportunidad",IF(S18="","",IF(AND(S18>0,S18<250),"Limitada",IF(OR(S18=250,AND(S18>250,S18<500)),"Media",IF(OR(S18=500,AND(S18>500,S18<750)),"Potencial",IF(OR(S18=750,AND(S18>750,S18<=1000)),"Sobresaliente",""))))),"")))) | U18: =IFERROR(VLOOKUP(T18,'4a. Parámetros de riesgo'!$C$31:$D$35,2,FALSE),IFERROR(VLOOKUP(T18,'4a. Parámetros de riesgo'!$I$31:$J$35,2,FALSE),"")) | V18: =IFERROR(VLOOKUP(U18,'4a. Parámetros de riesgo'!$D$31:$E$35,2,FALSE),IFERROR(VLOOKUP(U18,'4a. Parámetros de riesgo'!$J$31:$K$35,2,FALSE),""))
B19: Fortaleza | C19: ='2a. Análisis Foda'!B18:B18 -> Actualización constante de equipo tecnológico y sistemas informáticos. | D19: Positivo | S19: =IFERROR(VLOOKUP(P19,Naturaleza,2,FALSE)*VLOOKUP('4b. Matriz - Contexto'!Q19,Probabilidad,2,FALSE)*VLOOKUP('4b. Matriz - Contexto'!R19,Severidad,2,FALSE),"") | T19: =IF(B19="Debilidad",IF(S19="","",IF(AND(S19>0,S19<200),"Trivial",IF(OR(S19=200,AND(S19>200,S19<400)),"Tolerable",IF(OR(S19=400,AND(S19>400,S19<600)),"Moderado",IF(OR(S19=600,AND(S19>600,S19<800)),"Importante",IF(OR(S19=800,S19>800,S19<1000,S19=1000),"Intolerable","")))))),IF(B19="Amenaza",IF(S19="","",IF(AND(S19>0,S19<200),"Trivial",IF(OR(S19=200,AND(S19>200,S19<400)),"Tolerable",IF(OR(S19=400,AND(S19>400,S19<600)),"Moderado",IF(OR(S19=600,AND(S19>600,S19<800)),"Importante",IF(OR(S19=800,S19>800,S19<1000,S19=1000),"Intolerable","")))))),IF(B19="Fortaleza",IF(S19="","",IF(AND(S19>0,S19<250),"Limitada",IF(OR(S19=250,AND(S19>250,S19<500)),"Media",IF(OR(S19=500,AND(S19>500,S19<750)),"Potencial",IF(OR(S19=750,AND(S19>750,S19<=1000)),"Sobresaliente", ""))))), IF(B19="Oportunidad",IF(S19="","",IF(AND(S19>0,S19<250),"Limitada",IF(OR(S19=250,AND(S19>250,S19<500)),"Media",IF(OR(S19=500,AND(S19>500,S19<750)),"Potencial",IF(OR(S19=750,AND(S19>750,S19<=1000)),"Sobresaliente",""))))),"")))) | U19: =IFERROR(VLOOKUP(T19,'4a. Parámetros de riesgo'!$C$31:$D$35,2,FALSE),IFERROR(VLOOKUP(T19,'4a. Parámetros de riesgo'!$I$31:$J$35,2,FALSE),"")) | V19: =IFERROR(VLOOKUP(U19,'4a. Parámetros de riesgo'!$D$31:$E$35,2,FALSE),IFERROR(VLOOKUP(U19,'4a. Parámetros de riesgo'!$J$31:$K$35,2,FALSE),""))
B20: Fortaleza | C20: ='2a. Análisis Foda'!B20:B20 -> Las medidas de seguridad en el control de los registros y datos personales. | D20: Positivo | S20: =IFERROR(VLOOKUP(P20,Naturaleza,2,FALSE)*VLOOKUP('4b. Matriz - Contexto'!Q20,Probabilidad,2,FALSE)*VLOOKUP('4b. Matriz - Contexto'!R20,Severidad,2,FALSE),"") | T20: =IF(B20="Debilidad",IF(S20="","",IF(AND(S20>0,S20<200),"Trivial",IF(OR(S20=200,AND(S20>200,S20<400)),"Tolerable",IF(OR(S20=400,AND(S20>400,S20<600)),"Moderado",IF(OR(S20=600,AND(S20>600,S20<800)),"Importante",IF(OR(S20=800,S20>800,S20<1000,S20=1000),"Intolerable","")))))),IF(B20="Amenaza",IF(S20="","",IF(AND(S20>0,S20<200),"Trivial",IF(OR(S20=200,AND(S20>200,S20<400)),"Tolerable",IF(OR(S20=400,AND(S20>400,S20<600)),"Moderado",IF(OR(S20=600,AND(S20>600,S20<800)),"Importante",IF(OR(S20=800,S20>800,S20<1000,S20=1000),"Intolerable","")))))),IF(B20="Fortaleza",IF(S20="","",IF(AND(S20>0,S20<250),"Limitada",IF(OR(S20=250,AND(S20>250,S20<500)),"Media",IF(OR(S20=500,AND(S20>500,S20<750)),"Potencial",IF(OR(S20=750,AND(S20>750,S20<=1000)),"Sobresaliente", ""))))), IF(B20="Oportunidad",IF(S20="","",IF(AND(S20>0,S20<250),"Limitada",IF(OR(S20=250,AND(S20>250,S20<500)),"Media",IF(OR(S20=500,AND(S20>500,S20<750)),"Potencial",IF(OR(S20=750,AND(S20>750,S20<=1000)),"Sobresaliente",""))))),"")))) | U20: =IFERROR(VLOOKUP(T20,'4a. Parámetros de riesgo'!$C$31:$D$35,2,FALSE),IFERROR(VLOOKUP(T20,'4a. Parámetros de riesgo'!$I$31:$J$35,2,FALSE),"")) | V20: =IFERROR(VLOOKUP(U20,'4a. Parámetros de riesgo'!$D$31:$E$35,2,FALSE),IFERROR(VLOOKUP(U20,'4a. Parámetros de riesgo'!$J$31:$K$35,2,FALSE),""))
B21: Fortaleza | C21: ='2a. Análisis Foda'!B21:B21 -> Gratuidad de la Credencial para Votar. | D21: Positivo | S21: =IFERROR(VLOOKUP(P21,Naturaleza,2,FALSE)*VLOOKUP('4b. Matriz - Contexto'!Q21,Probabilidad,2,FALSE)*VLOOKUP('4b. Matriz - Contexto'!R21,Severidad,2,FALSE),"") | T21: =IF(B21="Debilidad",IF(S21="","",IF(AND(S21>0,S21<200),"Trivial",IF(OR(S21=200,AND(S21>200,S21<400)),"Tolerable",IF(OR(S21=400,AND(S21>400,S21<600)),"Moderado",IF(OR(S21=600,AND(S21>600,S21<800)),"Importante",IF(OR(S21=800,S21>800,S21<1000,S21=1000),"Intolerable","")))))),IF(B21="Amenaza",IF(S21="","",IF(AND(S21>0,S21<200),"Trivial",IF(OR(S21=200,AND(S21>200,S21<400)),"Tolerable",IF(OR(S21=400,AND(S21>400,S21<600)),"Moderado",IF(OR(S21=600,AND(S21>600,S21<800)),"Importante",IF(OR(S21=800,S21>800,S21<1000,S21=1000),"Intolerable","")))))),IF(B21="Fortaleza",IF(S21="","",IF(AND(S21>0,S21<250),"Limitada",IF(OR(S21=250,AND(S21>250,S21<500)),"Media",IF(OR(S21=500,AND(S21>500,S21<750)),"Potencial",IF(OR(S21=750,AND(S21>750,S21<=1000)),"Sobresaliente", ""))))), IF(B21="Oportunidad",IF(S21="","",IF(AND(S21>0,S21<250),"Limitada",IF(OR(S21=250,AND(S21>250,S21<500)),"Media",IF(OR(S21=500,AND(S21>500,S21<750)),"Potencial",IF(OR(S21=750,AND(S21>750,S21<=1000)),"Sobresaliente",""))))),"")))) | U21: =IFERROR(VLOOKUP(T21,'4a. Parámetros de riesgo'!$C$31:$D$35,2,FALSE),IFERROR(VLOOKUP(T21,'4a. Parámetros de riesgo'!$I$31:$J$35,2,FALSE),"")) | V21: =IFERROR(VLOOKUP(U21,'4a. Parámetros de riesgo'!$D$31:$E$35,2,FALSE),IFERROR(VLOOKUP(U21,'4a. Parámetros de riesgo'!$J$31:$K$35,2,FALSE),""))
B22: Debilidad | C22: ='2a. Análisis Foda'!L10:L10 -> Metodología deficiente para la capacitación. | D22: Negativo | S22: =IFERROR(VLOOKUP(P22,Naturaleza,2,FALSE)*VLOOKUP('4b. Matriz - Contexto'!Q22,Probabilidad,2,FALSE)*VLOOKUP('4b. Matriz - Contexto'!R22,Severidad,2,FALSE),"") | T22: =IF(B22="Debilidad",IF(S22="","",IF(AND(S22>0,S22<200),"Trivial",IF(OR(S22=200,AND(S22>200,S22<400)),"Tolerable",IF(OR(S22=400,AND(S22>400,S22<600)),"Moderado",IF(OR(S22=600,AND(S22>600,S22<800)),"Importante",IF(OR(S22=800,S22>800,S22<1000,S22=1000),"Intolerable","")))))),IF(B22="Amenaza",IF(S22="","",IF(AND(S22>0,S22<200),"Trivial",IF(OR(S22=200,AND(S22>200,S22<400)),"Tolerable",IF(OR(S22=400,AND(S22>400,S22<600)),"Moderado",IF(OR(S22=600,AND(S22>600,S22<800)),"Importante",IF(OR(S22=800,S22>800,S22<1000,S22=1000),"Intolerable","")))))),IF(B22="Fortaleza",IF(S22="","",IF(AND(S22>0,S22<250),"Limitada",IF(OR(S22=250,AND(S22>250,S22<500)),"Media",IF(OR(S22=500,AND(S22>500,S22<750)),"Potencial",IF(OR(S22=750,AND(S22>750,S22<=1000)),"Sobresaliente", ""))))), IF(B22="Oportunidad",IF(S22="","",IF(AND(S22>0,S22<250),"Limitada",IF(OR(S22=250,AND(S22>250,S22<500)),"Media",IF(OR(S22=500,AND(S22>500,S22<750)),"Potencial",IF(OR(S22=750,AND(S22>750,S22<=1000)),"Sobresaliente",""))))),"")))) | U22: =IFERROR(VLOOKUP(T22,'4a. Parámetros de riesgo'!$C$31:$D$35,2,FALSE),IFERROR(VLOOKUP(T22,'4a. Parámetros de riesgo'!$I$31:$J$35,2,FALSE),"")) | V22: =IFERROR(VLOOKUP(U22,'4a. Parámetros de riesgo'!$D$31:$E$35,2,FALSE),IFERROR(VLOOKUP(U22,'4a. Parámetros de riesgo'!$J$31:$K$35,2,FALSE),""))
B23: Debilidad | C23: ='2a. Análisis Foda'!L11:L11 -> Falta de oportunidad en la disposición de recursos. | D23: Negativo | S23: =IFERROR(VLOOKUP(P23,Naturaleza,2,FALSE)*VLOOKUP('4b. Matriz - Contexto'!Q23,Probabilidad,2,FALSE)*VLOOKUP('4b. Matriz - Contexto'!R23,Severidad,2,FALSE),"") | T23: =IF(B23="Debilidad",IF(S23="","",IF(AND(S23>0,S23<200),"Trivial",IF(OR(S23=200,AND(S23>200,S23<400)),"Tolerable",IF(OR(S23=400,AND(S23>400,S23<600)),"Moderado",IF(OR(S23=600,AND(S23>600,S23<800)),"Importante",IF(OR(S23=800,S23>800,S23<1000,S23=1000),"Intolerable","")))))),IF(B23="Amenaza",IF(S23="","",IF(AND(S23>0,S23<200),"Trivial",IF(OR(S23=200,AND(S23>200,S23<400)),"Tolerable",IF(OR(S23=400,AND(S23>400,S23<600)),"Moderado",IF(OR(S23=600,AND(S23>600,S23<800)),"Importante",IF(OR(S23=800,S23>800,S23<1000,S23=1000),"Intolerable","")))))),IF(B23="Fortaleza",IF(S23="","",IF(AND(S23>0,S23<250),"Limitada",IF(OR(S23=250,AND(S23>250,S23<500)),"Media",IF(OR(S23=500,AND(S23>500,S23<750)),"Potencial",IF(OR(S23=750,AND(S23>750,S23<=1000)),"Sobresaliente", ""))))), IF(B23="Oportunidad",IF(S23="","",IF(AND(S23>0,S23<250),"Limitada",IF(OR(S23=250,AND(S23>250,S23<500)),"Media",IF(OR(S23=500,AND(S23>500,S23<750)),"Potencial",IF(OR(S23=750,AND(S23>750,S23<=1000)),"Sobresaliente",""))))),"")))) | U23: =IFERROR(VLOOKUP(T23,'4a. Parámetros de riesgo'!$C$31:$D$35,2,FALSE),IFERROR(VLOOKUP(T23,'4a. Parámetros de riesgo'!$I$31:$J$35,2,FALSE),"")) | V23: =IFERROR(VLOOKUP(U23,'4a. Parámetros de riesgo'!$D$31:$E$35,2,FALSE),IFERROR(VLOOKUP(U23,'4a. Parámetros de riesgo'!$J$31:$K$35,2,FALSE),""))
